try { 
    throw Error('User already exit');
  
  } catch(e) {
    console.log(e)
  };